<?xml version="1.0" ?>
<!-- =================================================================================== -->
<!-- |    This document was autogenerated by xacro from tiago.urdf.xacro               | -->
<!-- |    EDITING THIS FILE BY HAND IS NOT RECOMMENDED                                 | -->
<!-- =================================================================================== -->
<!-- 
  Copyright (c) 2024 PAL Robotics S.L. All rights reserved.

  Licensed under the Apache License, Version 2.0 (the "License");
  you may not use this file except in compliance with the License.
  You may obtain a copy of the License at

      http://www.apache.org/licenses/LICENSE-2.0

  Unless required by applicable law or agreed to in writing, software
  distributed under the License is distributed on an "AS IS" BASIS,
  WITHOUT WARRANTIES OR CONDITIONS OF ANY KIND, either express or implied.
  See the License for the specific language governing permissions and
  limitations under the License.
 -->
<!--
  - Base
  - Laser
  - Arm
  - Wrist
  - FT Sensor
  - End effector
  - Camera
-->
<robot name="tiago">
  <!-- ARGUMENTS -->
  <!-- PROPERTIES -->
  <!-- INCLUDES -->
  <!-- PROPERTIES -->
  <!-- MACRO DEFINITION-->
  <material name="Blue">
    <color rgba="0.0 0.0 0.8 1.0"/>
  </material>
  <material name="Green">
    <color rgba="0.0 0.8 0.0 1.0"/>
  </material>
  <material name="Grey">
    <color rgba="0.7 0.7 0.7 1.0"/>
  </material>
  <material name="LightGrey">
    <color rgba="0.9 0.9 0.9 1.0"/>
  </material>
  <material name="DarkGrey">
    <color rgba="0.1 0.1 0.1 1.0"/>
  </material>
  <material name="Red">
    <color rgba="0.8 0.0 0.0 1.0"/>
  </material>
  <material name="White">
    <color rgba="1.0 1.0 1.0 1.0"/>
  </material>
  <material name="Yellow">
    <color rgba="0.96 0.88 0.14 1.0"/>
  </material>
  <material name="Black">
    <color rgba="0.0 0.0 0.0 1.0"/>
  </material>
  <material name="FlatBlack">
    <color rgba="0.09 0.09 0.09 1.0"/>
  </material>
  <material name="Orange">
    <color rgba="1.0 0.487 0.0 1.0"/>
  </material>
  <material name="pal/Orange">
    <color rgba="0.91373 0.61568 0.29411 1.0"/>
  </material>
  <material name="pal/DarkGrey">
    <color rgba="0.29804 0.29804 0.29804 1"/>
  </material>
  <!-- MACRO DEFINITION -->
  <!-- MACRO DEFINITION -->
  <!-- MACRO DEFINITION -->
  <!-- MACRO DEFINITION -->
  <!-- ROBOT DEFINITION -->
  
  <!-- Base -->
  <link name="base_link">
    <inertial>
      <origin rpy="0 0 0" xyz="-0.00000106 0.00000109 0.0000387"/>
      <mass value="28.26649"/>
      <inertia ixx="0.465408937" ixy="0.002160024" ixz="-0.001760255" iyy="0.483193291" iyz="-0.000655952" izz="0.550939703"/>
    </inertial>
    <visual>
      <origin rpy="0 0 0" xyz="0 0 0"/>
      <geometry>
        <mesh filename="package://pmb2_description/meshes/base/base.stl"/>
      </geometry>
      <material name="White"/>
    </visual>
    <collision>
      <origin rpy="0 0 0" xyz="0 0 0"/>
      <geometry>
        <mesh filename="package://pmb2_description/meshes/base/high_resolution/base_collision.stl"/>
      </geometry>
      <material name="White"/>
    </collision>
  </link>
  <!-- Base footprint -->
  <!--<link name="base_footprint"/>
  <joint name="base_footprint_joint" type="fixed">
    <origin rpy="0 0 0" xyz="0 0 0.0985"/>
    <child link="base_link"/>
    <parent link="base_footprint"/>
  </joint>-->
  
  
  
<link name="torso_fixed_link">
    <inertial>
      <origin rpy="0.00000 0.00000 0.00000" xyz="0.02435 -0.00464 0.15900"/>
      <mass value="14.01360"/>
      <inertia ixx="0.38341100000" ixy="0.00036400000" ixz="-0.02438900000" iyy="0.40577300000" iyz="-0.00078200000" izz="0.07699800000"/>
    </inertial>
    <visual>
      <origin rpy="0 0 0" xyz="0 0 0"/>
      <geometry>
        <mesh filename="package://tiago_description/meshes/torso/torso_fix.stl" scale="1 1 1"/>
      </geometry>
      <material name="LightGrey"/>
    </visual>
    <collision>
      <origin rpy="0 0 0" xyz="0.085 0.0 0.02"/>
      <geometry>
        <box size="0.4 0.25 0.04"/>
      </geometry>
    </collision>
    <collision>
      <origin rpy="0 0 0" xyz="0 0 0.05"/>
      <geometry>
        <box size="0.25 0.25 0.1"/>
      </geometry>
    </collision>
  </link>
  <joint name="torso_fixed_joint" type="fixed">
    <origin rpy="0 0 0" xyz="-0.062 0.0 0.193"/>
    <parent link="base_link"/>
    <child link="torso_fixed_link"/>
    <axis xyz="0 0 0"/>
  </joint>
  <!-- Middle extending  -->
  <!--  <link name="torso_fixed_column_link">
    <inertial>
      <origin rpy="0 0 0" xyz="0 0 0"/>
      <mass value="0.01"/>
      <inertia ixx="0.000001" ixy="0" ixz="0" iyy="0.000001" iyz="0" izz="0.000001"/>
    </inertial>
    <visual>
      <origin rpy="0 0 0" xyz="0 0 0.275"/>
      <geometry>
        <box size="0.18 0.2 0.55"/>
      </geometry>
      <material name="DarkGrey"/>
    </visual>
    <collision>
      <origin rpy="0 0 0" xyz="0 0 0.275"/>
      <geometry>
        <box size="0.23 0.23 0.55"/>
      </geometry>
      <material name="DarkGrey"/>
    </collision>
  </link>
  <gazebo reference="torso_fixed_column_link">
    <material>Gazebo/DarkGrey</material>
  </gazebo>
  <joint name="torso_fixed_column_joint" type="fixed">
    <origin rpy="0 0 0" xyz="-0.062 0.0 0.193"/>
    <parent link="base_link"/>
    <child link="torso_fixed_column_link"/>
    <axis xyz="0 0 0"/>
  </joint> -->
  
  <!-- Lifting body -->
  <link name="torso_lift_link">
    <inertial>
      <origin rpy="0.00000 0.00000 0.00000" xyz="0.04361 -0.00116 -0.17334"/>
      <mass value="6.93198"/>
      <inertia ixx="0.24487000000" ixy="-0.00145600000" ixz="-0.00974200000" iyy="0.24926900000" iyz="0.00828100000" izz="0.09039500000"/>
    </inertial>
    <visual>
      <origin rpy="0 0 0" xyz="0 0 0"/>
      <geometry>
        <mesh filename="package://tiago_description/meshes/torso/torso_lift_with_arm.stl" scale="1 1 1"/>
      </geometry>
      <material name="White"/>
    </visual>
    <collision>
      <origin rpy="0 0 0" xyz="0 0 0"/>
      <geometry>
        <mesh filename="package://tiago_description/meshes/torso/torso_lift_collision_core.dae" scale="1 1 1"/>
      </geometry>
      <material name="LightGrey"/>
    </collision>
    <collision>
      <origin rpy="0 0 0" xyz="0 0 0"/>
      <geometry>
        <mesh filename="package://tiago_description/meshes/torso/torso_lift_collision_shoulder.dae" scale="1 1 1"/>
      </geometry>
      <material name="LightGrey"/>
    </collision>
    <collision>
      <origin rpy="0 0 0" xyz="0 0 0"/>
      <geometry>
        <mesh filename="package://tiago_description/meshes/torso/torso_lift_collision_neck.dae" scale="1 1 1"/>
      </geometry>
      <material name="LightGrey"/>
    </collision>
  </link>
  <joint name="torso_lift_joint" type="prismatic">
    <origin rpy="0.0 0.0 0.0" xyz="0.0 0.0 0.597"/>
    <parent link="torso_fixed_link"/>
    <child link="torso_lift_link"/>
    <axis xyz="0 0 1"/>
    <limit effort="2000" lower="0" upper="0.35" velocity="0.07"/>
    <calibration rising="0.0"/>
    <dynamics damping="1000"/>
    <safety_controller k_position="20" k_velocity="20" soft_lower_limit="0.0" soft_upper_limit="0.35"/>
  </joint>
  
  <!-- Shoulder -->
  <link name="arm_1_link">
    <inertial>
      <!--<origin xyz="0.061191 ${reflect * -0.022397} -0.012835" rpy="0.00000 0.00000 0.00000"/>-->
      <origin rpy="0.00000 0.00000 0.00000" xyz="0.061191 -0.022397 -0.012835"/>
      <mass value="1.563428"/>
      <inertia ixx="0.002471" ixy="-0.001809" ixz="-0.001202" iyy="0.006132" iyz="0.000494" izz="0.006704"/>
    </inertial>
    <!-- M90 module -->
    <visual>
      <origin rpy="0 0 0" xyz="0 0 0"/>
      <geometry>
        <mesh filename="package://tiago_description/meshes/arm/arm_1.stl" scale="1 1 1"/>
      </geometry>
      <material name="White"/>
    </visual>
    <collision>
      <origin rpy="0 0 0" xyz="0 0 0"/>
      <geometry>
        <mesh filename="package://tiago_description/meshes/arm/arm_1_collision.dae" scale="1 1 1"/>
      </geometry>
    </collision>
  </link>
  <joint name="arm_1_joint" type="revolute">
    <parent link="torso_lift_link"/>
    <child link="arm_1_link"/>
    <origin rpy="0 0 -1.5707963267948966" xyz="0.15505 0.014 -0.151"/>
    <axis xyz="0 0 1"/>
    <limit effort="43.0" lower="0.0" upper="2.748893571891069" velocity="1.95"/>
    <dynamics damping="40.0" friction="1.0"/>
    <safety_controller k_position="20" k_velocity="20" soft_lower_limit="0.07" soft_upper_limit="2.678893571891069"/>
  </joint>
  <link name="arm_2_link">
    <inertial>
      <origin rpy="0.00000 0.00000 0.00000" xyz="0.030432 0.000229 -0.005942"/>
      <mass value="1.800397"/>
      <inertia ixx="0.001809" ixy="1.5e-05" ixz="0.000254" iyy="0.004333" iyz="1.4e-05" izz="0.004341"/>
    </inertial>
    <visual>
      <!-- <origin xyz="0 0 0" rpy="${180 * deg_to_rad} ${0 * deg_to_rad} ${-90 * deg_to_rad}" /> -->
      <origin rpy="0.0 0.0 0.0" xyz="0 0 0"/>
      <geometry>
        <mesh filename="package://tiago_description/meshes/arm/arm_2.stl" scale="1 1 1"/>
      </geometry>
      <material name="DarkGrey"/>
    </visual>
    <collision>
      <!-- <origin xyz="0 0 0" rpy="${180 * deg_to_rad} ${0 * deg_to_rad} ${-90 * deg_to_rad}" /> -->
      <origin rpy="0.0 0.0 0.0" xyz="0 0 0"/>
      <geometry>
        <mesh filename="package://tiago_description/meshes/arm/arm_2_collision.dae" scale="1 1 1"/>
      </geometry>
    </collision>
  </link>
  <joint name="arm_2_joint" type="revolute">
    <parent link="arm_1_link"/>
    <child link="arm_2_link"/>
    <origin rpy="1.5707963267948966 0.0 0.0" xyz="0.125 0.0195 -0.031"/>
    <axis xyz="0 0 1"/>
    <limit effort="43.0" lower="-1.5707963267948966" upper="1.090830782496456" velocity="1.95"/>
    <dynamics damping="40.0" friction="1.0"/>
    <safety_controller k_position="20" k_velocity="20" soft_lower_limit="-1.5007963267948965" soft_upper_limit="1.020830782496456"/>
  </joint>
  <link name="arm_3_link">
    <inertial>
      <origin rpy="0.00000 0.00000 0.00000" xyz="0.007418 -0.004361 -0.134194"/>
      <mass value="1.8"/>
      <inertia ixx="0.019541" ixy="-0.000105" ixz="-0.001717" iyy="0.019936" iyz="0.000852" izz="0.002864"/>
    </inertial>
    <visual>
      <origin rpy="0 0 0" xyz="0 0 0"/>
      <geometry>
        <mesh filename="package://tiago_description/meshes/arm/arm_3.stl" scale="1 1 1"/>
      </geometry>
      <material name="DarkGrey"/>
    </visual>
    <collision>
      <origin rpy="0 0 0" xyz="0 0 0"/>
      <geometry>
        <mesh filename="package://tiago_description/meshes/arm/arm_3_collision.dae" scale="1 1 1"/>
      </geometry>
    </collision>
  </link>
  <joint name="arm_3_joint" type="revolute">
    <parent link="arm_2_link"/>
    <child link="arm_3_link"/>
    <origin rpy="-1.5707963267948966 0.0 1.5707963267948966" xyz="0.0895 0.0 -0.0015"/>
    <axis xyz="0 0 1"/>
    <limit effort="26" lower="-3.5342917352885173" upper="1.5707963267948966" velocity="2.35"/>
    <dynamics damping="40.0" friction="1.0"/>
    <safety_controller k_position="20" k_velocity="20" soft_lower_limit="-3.4642917352885174" soft_upper_limit="1.5007963267948965"/>
  </joint>
  <!-- Elbow -->
  <link name="arm_4_link">
    <inertial>
      <origin rpy="0.00000 0.00000 0.00000" xyz="-0.095658 0.014666 0.018133"/>
      <mass value="1.432697"/>
      <inertia ixx="0.002040" ixy="0.000725" ixz="-0.00115" iyy="0.008424" iyz="-0.000204" izz="0.008686"/>
    </inertial>
    <visual>
      <origin rpy="0 0 0" xyz="0 0 0"/>
      <geometry>
        <mesh filename="package://tiago_description/meshes/arm/arm_4.stl" scale="1 1 1"/>
      </geometry>
      <material name="DarkGrey"/>
    </visual>
    <collision>
      <origin rpy="0 0 0" xyz="0 0 0"/>
      <geometry>
        <mesh filename="package://tiago_description/meshes/arm/arm_4_collision.dae" scale="1 1 1"/>
      </geometry>
    </collision>
  </link>
  <joint name="arm_4_joint" type="revolute">
    <parent link="arm_3_link"/>
    <child link="arm_4_link"/>
    <origin rpy="-1.5707963267948966 -1.5707963267948966 0.0" xyz="-0.02 -0.027 -0.222"/>
    <axis xyz="0 0 1"/>
    <limit effort="26" lower="-0.39269908169872414" upper="2.356194490192345" velocity="2.35"/>
    <dynamics damping="40.0" friction="1.0"/>
    <safety_controller k_position="20" k_velocity="20" soft_lower_limit="-0.32269908169872413" soft_upper_limit="2.286194490192345"/>
  </joint>
  <gazebo reference="arm_1_link">
    <mu1>0.9</mu1>
    <mu2>0.9</mu2>
    <material>Gazebo/DarkGrey</material>
  </gazebo>
  <gazebo reference="arm_2_link">
    <mu1>0.9</mu1>
    <mu2>0.9</mu2>
    <material>Gazebo/DarkGrey</material>
  </gazebo>
  <gazebo reference="arm_3_link">
    <mu1>0.9</mu1>
    <mu2>0.9</mu2>
    <material>Gazebo/DarkGrey</material>
  </gazebo>
  <gazebo reference="arm_4_link">
    <mu1>0.9</mu1>
    <mu2>0.9</mu2>
    <material>Gazebo/DarkGrey</material>
  </gazebo>
  <gazebo reference="arm_1_joint">
    <implicitSpringDamper>1</implicitSpringDamper>
  </gazebo>
  <gazebo reference="arm_2_joint">
    <implicitSpringDamper>1</implicitSpringDamper>
  </gazebo>
  <gazebo reference="arm_3_joint">
    <implicitSpringDamper>1</implicitSpringDamper>
  </gazebo>
  <gazebo reference="arm_4_joint">
    <implicitSpringDamper>1</implicitSpringDamper>
  </gazebo>
  <!-- Wrist-->
  <link name="arm_5_link">
    <inertial>
      <origin rpy="0.00000 0.00000 0.00000" xyz="0.001078 -0.000151 -0.077173"/>
      <mass value="0.9359143689"/>
      <inertia ixx="0.001036187977" ixy="1.0622321E-07" ixz="1.9920336E-06" iyy="0.000794527176366096" iyz="-2.56396106998404E-07" izz="0.000439831229979178"/>
    </inertial>
    <visual>
      <origin rpy="0 0 0" xyz="0 0 0"/>
      <geometry>
        <mesh filename="package://tiago_description/meshes/arm/arm_5-wrist-2017.stl" scale="1 1 1"/>
      </geometry>
      <material name="LightGrey"/>
    </visual>
    <collision>
      <origin rpy="0 0 0" xyz="0 0 0"/>
      <geometry>
        <mesh filename="package://tiago_description/meshes/arm/arm_5_collision-wrist-2017.dae" scale="1 1 1"/>
      </geometry>
    </collision>
  </link>
  <joint name="arm_5_joint" type="revolute">
    <parent link="arm_4_link"/>
    <child link="arm_5_link"/>
    <origin rpy="1.5707963267948966 -1.5707963267948966 -1.5707963267948966" xyz="-0.162 0.02 0.027"/>
    <axis xyz="0 0 1"/>
    <limit effort="3" lower="-2.0943951023931953" upper="2.0943951023931953" velocity="1.95"/>
    <dynamics damping="1.0" friction="1.0"/>
    <safety_controller k_position="20" k_velocity="20" soft_lower_limit="-2.0743951023931952" soft_upper_limit="2.0743951023931952"/>
  </joint>
  <link name="arm_6_link">
    <inertial>
      <origin rpy="0.00000 0.00000 0.00000" xyz="-0.000153 -0.003122 0.000183"/>
      <mass value="0.30275767222"/>
      <inertia ixx="3.29233557E-05" ixy="6.31537395E-08" ixz="-4.567124912E-11" iyy="3.85334410118923E-05" iyz="-2.01613082836742E-07" izz="3.33282849168039E-05"/>
    </inertial>
    <visual>
      <origin rpy="0 0 0" xyz="0 0 0"/>
      <geometry>
        <mesh filename="package://tiago_description/meshes/arm/arm_6-wrist-2017.stl" scale="1 1 1"/>
      </geometry>
      <material name="LightGrey"/>
    </visual>
    <collision>
      <origin rpy="0 0 0" xyz="0 0 0"/>
      <geometry>
        <mesh filename="package://tiago_description/meshes/arm/arm_6_collision-wrist-2017.dae" scale="1 1 1"/>
      </geometry>
    </collision>
  </link>
  <joint name="arm_6_joint" type="revolute">
    <parent link="arm_5_link"/>
    <child link="arm_6_link"/>
    <origin rpy="0.0 -1.5707963267948966 -1.5707963267948966" xyz="0 0 0.15"/>
    <axis xyz="0 0 1"/>
    <limit effort="6.6" lower="-1.413716694115407" upper="1.413716694115407" velocity="1.76"/>
    <dynamics damping="1.0" friction="1.0"/>
    <safety_controller k_position="20" k_velocity="20" soft_lower_limit="-1.3937166941154069" soft_upper_limit="1.3937166941154069"/>
  </joint>
  <link name="arm_7_link">
    <inertial>
      <origin rpy="0.00000 0.00000 0.00000" xyz="0.000010 -0.000003 -0.007774"/>
      <mass value="0.100"/>
      <inertia ixx="1.14959795E-05" ixy="-1.390727219E-07" ixz="5.930207406E-09" iyy="1.13594084240734E-05" iyz="-1.78396260812528E-08" izz="2.01898984804048E-05"/>
    </inertial>
  </link>
  <joint name="arm_7_joint" type="revolute">
    <parent link="arm_6_link"/>
    <child link="arm_7_link"/>
    <origin rpy="1.5707963267948966 0.0 1.5707963267948966" xyz="0 0 0"/>
    <axis xyz="0 0 1"/>
    <limit effort="6.6" lower="-2.0943951023931953" upper="2.0943951023931953" velocity="1.76"/>
    <dynamics damping="1.0" friction="1.0"/>
    <safety_controller k_position="20" k_velocity="20" soft_lower_limit="-2.0743951023931952" soft_upper_limit="2.0743951023931952"/>
  </joint>
  <gazebo reference="arm_5_link">
    <mu1>0.9</mu1>
    <mu2>0.9</mu2>
  </gazebo>
  <gazebo reference="arm_6_link">
    <mu1>0.9</mu1>
    <mu2>0.9</mu2>
  </gazebo>
  <gazebo reference="arm_7_link">
    <mu1>0.9</mu1>
    <mu2>0.9</mu2>
  </gazebo>
  <gazebo reference="arm_5_joint">
    <implicitSpringDamper>1</implicitSpringDamper>
  </gazebo>
  <gazebo reference="arm_6_joint">
    <implicitSpringDamper>1</implicitSpringDamper>
  </gazebo>
  <gazebo reference="arm_7_joint">
    <implicitSpringDamper>1</implicitSpringDamper>
    <provideFeedback>1</provideFeedback>
  </gazebo>
  <!-- Tool -->
  <link name="arm_tool_link">
    <inertial>
      <mass value="0.1"/>
      <inertia ixx="0.0" ixy="0.0" ixz="0.0" iyy="0.0" iyz="0.0" izz="0.0"/>
    </inertial>
    <visual>
      <origin rpy="0 1.5707963267948966 0" xyz="0.001 0 0"/>
      <geometry>
        <cylinder length="0.005" radius="0.005"/>
      </geometry>
      <material name="LightGrey"/>
    </visual>
    <collision>
      <origin rpy="0 1.5707963267948966 0" xyz="0.001 0 0"/>
      <geometry>
        <cylinder length="0.005" radius="0.005"/>
      </geometry>
    </collision>
  </link>
  <joint name="arm_tool_joint" type="fixed">
    <parent link="arm_7_link"/>
    <child link="arm_tool_link"/>
    <origin rpy="1.5707963267948966 -1.5707963267948966 3.141592653589793" xyz="0 0 0.051875"/>
  </joint>
  <!-- FT sensor-->
  <link name="wrist_ft_link">
    <inertial>
      <mass value="0.095000"/>
      <inertia ixx="0.000016" ixy="-0.000001" ixz="0.0" iyy="0.000015" iyz="0.0" izz="0.000027"/>
    </inertial>
    <visual>
      <origin rpy="0 0 0" xyz="0 0 0"/>
      <geometry>
        <cylinder length="0.0157" radius="0.0225"/>
      </geometry>
      <material name="LightGrey"/>
    </visual>
    <collision>
      <origin rpy="0 0 0" xyz="0 0 0"/>
      <geometry>
        <cylinder length="0.0157" radius="0.0225"/>
      </geometry>
    </collision>
  </link>
  <joint name="wrist_ft_joint" type="fixed">
    <parent link="arm_tool_link"/>
    <child link="wrist_ft_link"/>
    <origin rpy="1.5707963267948966 0 1.5707963267948966" xyz="0.009375 0 0"/>
  </joint>
  
  
  <!-- FT tool -->
  <link name="wrist_ft_tool_link">
    <inertial>
      <mass value="0.1"/>
      <inertia ixx="0.0" ixy="0.0" ixz="0.0" iyy="0.0" iyz="0.0" izz="0.0"/>
    </inertial>
    <visual>
      <origin rpy="0 1.5707963267948966 0" xyz="0.0 0 0"/>
      <geometry>
        <cylinder length="0.00975" radius="0.025"/>
      </geometry>
      <material name="FlatBlack"/>
    </visual>
    <collision>
      <origin rpy="0 1.5707963267948966 0" xyz="0.0 0 0"/>
      <geometry>
        <cylinder length="0.00975" radius="0.025"/>
      </geometry>
    </collision>
  </link>
  <joint name="wrist_tool_joint" type="fixed">
    <parent link="wrist_ft_link"/>
    <child link="wrist_ft_tool_link"/>
    <origin rpy="-1.5707963267948966 -1.5707963267948966 0" xyz="0 0 0.0112"/>
  </joint>
  <gazebo reference="wrist_ft_joint">
    <preserveFixedJoint>true</preserveFixedJoint>
    <!-- in case this is in a fixed joint -->
    <sensor name="wrist_ft_sensor" type="force_torque">
      <update_rate>100</update_rate>
      <visualize>true</visualize>
      <force_torque>
        <frame>child</frame>
        <measure_direction>child_to_parent</measure_direction>
      </force_torque>
    </sensor>
  </gazebo>
  
  
  <!-- Aggiunta da qui -->
  <!-- <link name="hand_tool_link">
    <inertial>
      <origin rpy="0 0 0" xyz="0 0 0"/>
      <mass value="0.0001"/>
      <inertia ixx="0.00001" ixy="0.0" ixz="0.0" iyy="0.00001" iyz="0.0" izz="0.00001"/>
    </inertial>
  </link>-->
  
  <!--<joint name="hand_tool_joint" type="fixed">
    <origin rpy="0 0 0" xyz="0 0 0"/>
    <parent link="wrist_ft_tool_link"/>
    <child link="hand_tool_link"/>
    <axis xyz="0 0 0"/>
  </joint> -->
  <joint name="hand_palm_joint" type="fixed">
    <parent link="wrist_ft_tool_link"/>
    <child link="hand_palm_link"/>
    <origin rpy="0 0 0" xyz="0 0 0"/>
  </joint>
  
   <link name="hand_palm_link">
    <inertial>
      <origin rpy="0 0 0" xyz="0.0641 -0.0022 0.0021"/>
      <mass value="0.4"/>
      <inertia ixx="0.000305100" ixy="0.000005037" ixz="0.000015302" iyy="0.000811920" iyz="0.000007622" izz="0.000655851"/>
    </inertial>
    <visual>
      <origin rpy="0 0 0" xyz="0 0 0"/>
      <geometry>
        <mesh filename="package://pal_hey5_description/meshes/palm.stl" scale="1 1 1"/>
      </geometry>
      <material name="DarkGrey"/>
    </visual>
    <collision>
      <origin rpy="0 0 0" xyz="0 0 0"/>
      <geometry>
        <mesh filename="package://pal_hey5_description/meshes/palm_collision.stl" scale="1 1 1"/>
      </geometry>
    </collision>
  </link>
  
  <link name="hand_grasping_frame"/>
  <joint name="hand_grasping_fixed_joint" type="fixed">
    <parent link="hand_palm_link"/>
    <child link="hand_grasping_frame"/>
    <axis xyz="0 0 1"/>
    <origin rpy="0 0 0" xyz="0.13 0.02 0"/>
  </joint>
  
  <!--<joint name="hand_safety_box_joint" type="fixed">
    <parent link="wrist_ft_tool_link"/>
    <child link="hand_safety_box"/>
    <origin rpy="0 0 0" xyz="0.1 0.02 0.02"/>
  </joint>
  <link name="hand_safety_box">
    <collision>
      <origin rpy="0 0 0" xyz="0 0 0"/>
      <geometry>
        <box size="0.2 0.115 0.18"/>
      </geometry>
    </collision>
  </link>-->
  
  <!-- A qui -->
  
  <!-- Tool Link -->
  <!-- <link name="hand_tool_link">
    <inertial>
      <origin rpy="0 0 0" xyz="0 0 0"/>
      <mass value="0.0001"/>
      <inertia ixx="0.00001" ixy="0.0" ixz="0.0" iyy="0.00001" iyz="0.0" izz="0.00001"/>
    </inertial>
  </link>
  <joint name="hand_tool_joint" type="fixed">
    <origin rpy="0 0 0" xyz="0 0 0"/>
    <parent link="wrist_ft_tool_link"/>
    <child link="hand_tool_link"/>
    <axis xyz="0 0 0"/>
  </joint>-->
  
  
  
  <!-- Custom -->
  <!--xacro:if value="${end_effector == 'custom' and not tiago_dual}">
    <xacro:include filename="$(find custom_ee_description)/urdf/end-effector.urdf.xacro" />
      <xacro:end_effector parent="${parent}">
        <origin xyz="0.01 0 0" rpy="${90*deg_to_rad} ${90*deg_to_rad} ${-90*deg_to_rad}"/>
      </xacro:end_effector>
    </xacro:if-->
  <!-- Custom dual-->
  <!--xacro:if value="${end_effector == 'custom' and tiago_dual}">
      <xacro:if value="${reflect == 1}"-->
  <!-- If right -->
  <!--xacro:include filename="$(find custom_dual_ee_description)/urdf/end-effector-right.urdf.xacro" />
    <xacro:end_effector_right parent="${parent}">
      <origin xyz="0.01 0 0" rpy="${90*deg_to_rad} ${90*deg_to_rad} ${-90*deg_to_rad}"/>
    </xacro:end_effector_right>
    </xacro:if>
    <xacro:if value="${reflect == -1}"-->
  <!-- If left -->
  <!--xacro:include filename="$(find custom_dual_ee_description)/urdf/end-effector-left.urdf.xacro" />
    <xacro:end_effector_left parent="${parent}">
      <origin xyz="0.01 0 0" rpy="${90*deg_to_rad} ${90*deg_to_rad} ${-90*deg_to_rad}"/>
    </xacro:end_effector_left>
    </xacro:if>
  </xacro:if-->
  
  <!-- ROS 2 control config-->
  <ros2_control name="ros2_control_tiago_system" type="system">
    <!-- Execution env config -->
    <hardware>
      <plugin>robot_control/RobotControl</plugin>
    </hardware>
    <joint name="wheel_right_joint">
      <command_interface name="velocity">
        <param name="min">-1</param>
        <param name="max">1</param>
      </command_interface>
      <state_interface name="position"/>
    </joint>
    <transmission name="wheel_right_trans">
      <plugin>transmission_interface/SimpleTransmission</plugin>
      <actuator name="wheel_right_actuator" role="actuator1"/>
      <joint name="wheel_right_joint" role="joint1">
        <mechanical_reduction>1.0</mechanical_reduction>
      </joint>
    </transmission>
    <joint name="wheel_left_joint">
      <command_interface name="velocity">
        <param name="min">-1</param>
        <param name="max">1</param>
      </command_interface>
      <state_interface name="position"/>
    </joint>
    <transmission name="wheel_left_trans">
      <plugin>transmission_interface/SimpleTransmission</plugin>
      <actuator name="wheel_left_actuator" role="actuator1"/>
      <joint name="wheel_left_joint" role="joint1">
        <mechanical_reduction>1.0</mechanical_reduction>
      </joint>
    </transmission>
    <joint name="torso_lift_joint">
      <command_interface name="position"/>
      <state_interface name="position"/>
      <state_interface name="velocity"/>
      <state_interface name="effort"/>
    </joint>
    <transmission name="torso_lift_trans">
      <plugin>transmission_interface/SimpleTransmission</plugin>
      <actuator name="torso_lift_actuator" role="actuator1"/>
      <joint name="torso_lift_joint" role="joint1">
        <mechanical_reduction>1.0</mechanical_reduction>
        <offset>0.0</offset>
      </joint>
    </transmission>
    <joint name="arm_1_joint">
      <command_interface name="position"/>
      <command_interface name="velocity"/>
      <command_interface name="effort"/>
      <state_interface name="position"/>
      <state_interface name="velocity"/>
      <state_interface name="effort"/>
    </joint>
    <transmission name="arm_1_trans">
      <plugin>transmission_interface/SimpleTransmission</plugin>
      <actuator name="arm_1_actuator" role="actuator1"/>
      <joint name="arm_1_joint" role="joint1">
        <mechanical_reduction>1.0</mechanical_reduction>
        <offset>0.0</offset>
      </joint>
    </transmission>
    <joint name="arm_2_joint">
      <command_interface name="position"/>
      <command_interface name="velocity"/>
      <command_interface name="effort"/>
      <state_interface name="position"/>
      <state_interface name="velocity"/>
      <state_interface name="effort"/>
    </joint>
    <transmission name="arm_2_trans">
      <plugin>transmission_interface/SimpleTransmission</plugin>
      <actuator name="arm_2_actuator" role="actuator1"/>
      <joint name="arm_2_joint" role="joint1">
        <mechanical_reduction>1.0</mechanical_reduction>
        <offset>0.0</offset>
      </joint>
    </transmission>
    <joint name="arm_3_joint">
      <command_interface name="position"/>
      <command_interface name="velocity"/>
      <command_interface name="effort"/>
      <state_interface name="position"/>
      <state_interface name="velocity"/>
      <state_interface name="effort"/>
    </joint>
    <transmission name="arm_3_trans">
      <plugin>transmission_interface/SimpleTransmission</plugin>
      <actuator name="arm_3_actuator" role="actuator1"/>
      <joint name="arm_3_joint" role="joint1">
        <mechanical_reduction>1.0</mechanical_reduction>
        <offset>0.0</offset>
      </joint>
    </transmission>
    <joint name="arm_4_joint">
      <command_interface name="position"/>
      <command_interface name="velocity"/>
      <command_interface name="effort"/>
      <state_interface name="position"/>
      <state_interface name="velocity"/>
      <state_interface name="effort"/>
    </joint>
    <transmission name="arm_4_trans">
      <plugin>transmission_interface/SimpleTransmission</plugin>
      <actuator name="arm_4_actuator" role="actuator1"/>
      <joint name="arm_4_joint" role="joint1">
        <mechanical_reduction>1.0</mechanical_reduction>
        <offset>0.0</offset>
      </joint>
    </transmission>
    <joint name="arm_5_joint">
      <command_interface name="position"/>
      <command_interface name="velocity"/>
      <command_interface name="effort"/>
      <state_interface name="position"/>
      <state_interface name="velocity"/>
      <state_interface name="effort"/>
    </joint>
    <transmission name="arm_5_trans">
      <plugin>transmission_interface/SimpleTransmission</plugin>
      <actuator name="arm_5_actuator" role="actuator1"/>
      <joint name="arm_5_joint" role="joint1">
        <mechanical_reduction>1.0</mechanical_reduction>
        <offset>0.0</offset>
      </joint>
    </transmission>
    <joint name="arm_6_joint">
      <command_interface name="position"/>
      <command_interface name="velocity"/>
      <command_interface name="effort"/>
      <state_interface name="position"/>
      <state_interface name="velocity"/>
      <state_interface name="effort"/>
    </joint>
    <joint name="arm_7_joint">
      <command_interface name="position"/>
      <command_interface name="velocity"/>
      <command_interface name="effort"/>
      <state_interface name="position"/>
      <state_interface name="velocity"/>
      <state_interface name="effort"/>
    </joint>
    <transmission name="arm_6_arm_7_wrist_trans">
      <plugin>transmission_interface/DifferentialTransmission</plugin>
      <actuator name="arm_6_actuator" role="actuator1">
        <mechanical_reduction>-1.0</mechanical_reduction>
      </actuator>
      <actuator name="arm_7_actuator" role="actuator2">
        <mechanical_reduction>1.0</mechanical_reduction>
      </actuator>
      <joint name="arm_6_joint" role="joint1">
        <mechanical_reduction>1.0</mechanical_reduction>
        <offset>0.0</offset>
      </joint>
      <joint name="arm_7_joint" role="joint2">
        <mechanical_reduction>-1.0</mechanical_reduction>
        <offset>0.0</offset>
      </joint>
    </transmission>
    <sensor name="wrist_ft_sensor">
      <state_interface name="force.x"/>
      <state_interface name="force.y"/>
      <state_interface name="force.z"/>
      <state_interface name="torque.x"/>
      <state_interface name="torque.y"/>
      <state_interface name="torque.z"/>
    </sensor>
    <joint name="hand_thumb_joint">
      <command_interface name="position"/>
      <state_interface name="position"/>
      <state_interface name="velocity"/>
      <state_interface name="effort"/>
    </joint>
    <transmission name="hand_thumb_trans">
      <plugin>transmission_interface/SimpleTransmission</plugin>
      <actuator name="hand_thumb_actuator" role="actuator1"/>
      <joint name="hand_thumb_joint" role="joint1">
        <mechanical_reduction>1.0</mechanical_reduction>
      </joint>
    </transmission>
    <joint name="hand_index_joint">
      <command_interface name="position"/>
      <state_interface name="position"/>
      <state_interface name="velocity"/>
      <state_interface name="effort"/>
    </joint>
    <transmission name="hand_index_trans">
      <plugin>transmission_interface/SimpleTransmission</plugin>
      <actuator name="hand_index_actuator" role="actuator1"/>
      <joint name="hand_index_joint" role="joint1">
        <mechanical_reduction>1.0</mechanical_reduction>
      </joint>
    </transmission>
    <joint name="hand_mrl_joint">
      <command_interface name="position"/>
      <state_interface name="position"/>
      <state_interface name="velocity"/>
      <state_interface name="effort"/>
    </joint>
    <transmission name="hand_mrl_trans">
      <plugin>transmission_interface/SimpleTransmission</plugin>
      <actuator name="hand_mrl_actuator" role="actuator1"/>
      <joint name="hand_mrl_joint" role="joint1">
        <mechanical_reduction>1.0</mechanical_reduction>
      </joint>
    </transmission>
    <joint name="head_1_joint">
      <command_interface name="position"/>
      <state_interface name="position"/>
      <state_interface name="velocity"/>
      <state_interface name="effort"/>
    </joint>
    <transmission name="head_1_trans">
      <plugin>transmission_interface/SimpleTransmission</plugin>
      <actuator name="head_1_actuator" role="actuator1"/>
      <joint name="head_1_joint" role="joint1">
        <mechanical_reduction>1.0</mechanical_reduction>
        <offset>0.0</offset>
      </joint>
    </transmission>
    <joint name="head_2_joint">
      <command_interface name="position"/>
      <state_interface name="position"/>
      <state_interface name="velocity"/>
      <state_interface name="effort"/>
    </joint>
    <transmission name="head_2_trans">
      <plugin>transmission_interface/SimpleTransmission</plugin>
      <actuator name="head_2_actuator" role="actuator1"/>
      <joint name="head_2_joint" role="joint1">
        <mechanical_reduction>1.0</mechanical_reduction>
        <offset>0.0</offset>
      </joint>
    </transmission>
  </ros2_control>
</robot>
